Workbook

Sheet 106
B1: 春秋六班学生考试成绩分析图表
B2: 姓名 | C2: 语文 原始 | D2: 语文 排名 | E2: 数学 原始 | F2: 数学 排名 | G2: 外语 原始 | H2: 外语 排名 | I2: 历史 原始 | J2: 历史 排名 | K2: 政治 赋分 | L2: 政治 排名 | M2: 地理 赋分 | N2: 地理 排名 | O2: 赋分 总分 | P2: 六总 级排 | Q2: 语数英 | R2: 三总 级排 | S2: 语数英+历史 | T2: 四总 级排 | U2: 原始排名 | V2: 进浮
B3: 谢凤仪 | C3: 缺考 | E3: 缺考 | G3: 缺考 | I3: 缺考 | O3: 缺考 | Q3: 缺考 | S3: 缺考 | U3: 101 | V3: =U3-P3 -> #VALUE!
B4: 钟文海 | C4: 缺考 | E4: 缺考 | G4: 缺考 | I4: 缺考 | O4: 缺考 | Q4: 缺考 | S4: 缺考 | U4: 3 | V4: =U4-P4 -> #VALUE!
B5: 刘益铭 | C5: 86 | D5: 143 | E5: 37 | F5: 141 | G5: 85 | H5: 77 | I5: 66 | J5: 116 | K5: 43 | L5: 193 | M5: 66 | N5: 72 | O5: 383 | P5: 163 | Q5: 208 | R5: 139 | S5: 274 | T5: 139 | U5: 75 | V5: =U5-P5 -> -88
B6: 邵凯恒 | C6: 81 | D6: 171 | E6: 51 | F6: 88 | G6: 57 | H6: 153 | I6: 54 | J6: 183 | K6: 73 | L6: 68 | M6: 77 | N6: 33 | O6: 393 | P6: 153 | Q6: 189 | R6: 163 | S6: 243 | T6: 178 | U6: 122 | V6: =U6-P6 -> -31
B7: 郭晓欣 | C7: 88 | D7: 127 | E7: 37 | F7: 141 | G7: 78 | H7: 96 | I7: 61 | J7: 154 | K7: 73 | L7: 68 | M7: 66 | N7: 72 | O7: 403 | P7: 145 | Q7: 203 | R7: 149 | S7: 264 | T7: 154 | U7: 99 | V7: =U7-P7 -> -46
B8: 关颖菲 | C8: 90 | D8: 116 | E8: 33 | F8: 161 | G8: 84 | H8: 82 | I8: 64 | J8: 132 | K8: 71 | L8: 87 | M8: 63 | N8: 81 | O8: 405 | P8: 142 | Q8: 207 | R8: 141 | S8: 271 | T8: 145 | U8: 48 | V8: =U8-P8 -> -94
B9: 谭伟乔 | C9: 97 | D9: 64 | E9: 41 | F9: 129 | G9: 58 | H9: 150 | I9: 78 | J9: 18 | K9: 66 | L9: 128 | M9: 74 | N9: 43 | O9: 414 | P9: 130 | Q9: 196 | R9: 158 | S9: 274 | T9: 139 | U9: 0 | V9: =U9-P9 -> -130
B10: 邓依梵 | C10: 97 | D10: 64 | E10: 34 | F10: 156 | G10: 93 | H10: 11 | I10: 66 | J10: 116 | K10: 69 | L10: 113 | M10: 59 | N10: 87 | O10: 418 | P10: 122 | Q10: 224 | R10: 97 | S10: 290 | T10: 100 | U10: 61 | V10: =U10-P10 -> -61
B11: 简芷晴 | C11: 91 | D11: 109 | E11: 51 | F11: 88 | G11: 74 | H11: 107 | I11: 67 | J11: 107 | K11: 56 | L11: 177 | M11: 92 | N11: 1 | O11: 431 | P11: 105 | Q11: 216 | R11: 122 | S11: 283 | T11: 121 | U11: 100 | V11: =U11-P11 -> -5
B12: 麦晓勤 | C12: 94 | D12: 87 | E12: 87 | F12: 11 | G12: 52 | H12: 163 | I12: 71 | J12: 63 | K12: 53 | L12: 181 | M12: 74 | N12: 43 | O12: 431 | P12: 105 | Q12: 233 | R12: 75 | S12: 304 | T12: 74 | U12: 134 | V12: =U12-P12 -> 29
B13: 莫思桐 | C13: 104 | D13: 19 | E13: 27 | F13: 175 | G13: 88 | H13: 69 | I13: 70 | J13: 71 | K13: 76 | L13: 52 | M13: 70 | N13: 60 | O13: 435 | P13: 100 | Q13: 219 | R13: 110 | S13: 289 | T13: 107 | U13: 74 | V13: =U13-P13 -> -26
B14: 吴怡璇 | C14: 80 | D14: 175 | E14: 49 | F14: 94 | G14: 111 | H14: 14 | I14: 61 | J14: 154 | K14: 76 | L14: 52 | M14: 58 | N14: 91 | O14: 435 | P14: 100 | Q14: 240 | R14: 64 | S14: 301 | T14: 80 | U14: 98 | V14: =U14-P14 -> -2
B15: 张媛琪 | C15: 98 | D15: 55 | E15: 34 | F15: 156 | G15: 101 | H15: 30 | I15: 57 | J15: 171 | K15: 61 | L15: 156 | M15: 86 | N15: 3 | O15: 437 | P15: 95 | Q15: 233 | R15: 75 | S15: 290 | T15: 100 | U15: 58 | V15: =U15-P15 -> -37
B16: 卿佩 | C16: 99 | D16: 48 | E16: 28 | F16: 173 | G16: 97 | H16: 34 | I16: 66 | J16: 116 | K16: 84 | L16: 14 | M16: 63 | N16: 81 | O16: 437 | P16: 95 | Q16: 224 | R16: 97 | S16: 290 | T16: 100 | U16: 115 | V16: =U16-P16 -> 20
... B58: 赖银婷 | C58: 104 | D58: 19 | E58: 106 | F58: 1 | G58: 97 | H58: 34 | I58: 83 | J58: 4 | K58: 84 | L58: 12 | M58: 82 | N58: 16 | O58: 556 | P58: 1 | Q58: 307 | R58: 1 | S58: 390 | T58: 1 | U58: 2 | V58: =U58-P58 -> 1

Sheet 统考成绩
A1: 学校 | B1: 行政班 | C1: 姓名 | D1: 新高考总分 | G1: 新高考语数英总分 | J1: 新高考3+1总分 | M1: 新高考原始总分 | P1: 语文 | S1: 数学 | V1: 英语 | Y1: 历史 | AB1: 政治 | AG1: 地理
D2: 分数 | E2: 校排 | F2: 班排 | G2: 分数 | H2: 校排 | I2: 班排 | J2: 分数 | K2: 校排 | L2: 班排 | M2: 分数 | N2: 校排 | O2: 班排 | P2: 分数 | Q2: 校排 | R2: 班排 | S2: 分数 | T2: 校排 | U2: 班排 | V2: 分数 | W2: 校排 | X2: 班排 | Y2: 分数 | Z2: 校排 | AA2: 班排 | AB2: 分数 | AC2: 等级 | AD2: 赋分 | AE2: 校排 | AF2: 班排 | AG2: 分数 | AH2: 等级 | AI2: 赋分 | AJ2: 校排 | AK2: 班排
A3: 大沥高中 | B3: 106班 | C3: 赖银婷 | D3: 556 | E3: 1 | F3: 1 | G3: 307 | H3: 1 | I3: 1 | J3: 390 | K3: 1 | L3: 1 | M3: 516 | N3: 1 | O3: 1 | P3: 104 | Q3: 19 | R3: 10 | S3: 106 | T3: 1 | U3: 1 | V3: 97 | W3: 34 | X3: 18 | Y3: 83 | Z3: 4 | AA3: 1 | AB3: 58 | AC3: A | AD3: 84 | AE3: 12 | AF3: 7 | AG3: 68 | AH3: B | AI3: 82 | AJ3: 16 | AK3: 12
A4: 大沥高中 | B4: 106班 | C4: 陈颖怡 | D4: 538 | E4: 2 | F4: 2 | G4: 304 | H4: 2 | I4: 2 | J4: 372 | K4: 3 | L4: 2 | M4: 499 | N4: 2 | O4: 2 | P4: 105 | Q4: 17 | R4: 8 | S4: 87 | T4: 11 | U4: 7 | V4: 112 | W4: 11 | X4: 7 | Y4: 68 | Z4: 94 | AA4: 33 | AB4: 53 | AC4: B | AD4: 80 | AE4: 28 | AF4: 13 | AG4: 74 | AH4: A | AI4: 86 | AJ4: 3 | AK4: 3
A5: 大沥高中 | B5: 106班 | C5: 麦道奇 | D5: 535 | E5: 3 | F5: 3 | G5: 292 | H5: 5 | I5: 4 | J5: 370 | K5: 4 | L5: 3 | M5: 494 | N5: 4 | O5: 4 | P5: 109 | Q5: 8 | R5: 4 | S5: 65 | T5: 47 | U5: 18 | V5: 118 | W5: 4 | X5: 2 | Y5: 78 | Z5: 18 | AA5: 8 | AB5: 56 | AC5: A | AD5: 83 | AE5: 19 | AF5: 11 | AG5: 68 | AH5: B | AI5: 82 | AJ5: 16 | AK5: 12
A6: 大沥高中 | B6: 106班 | C6: 周楚莹 | D6: 534 | E6: 4 | F6: 4 | G6: 287 | H6: 6 | I6: 5 | J6: 367 | K6: 5 | L6: 4 | M6: 497 | N6: 3 | O6: 3 | P6: 114 | Q6: 1 | R6: 1 | S6: 88 | T6: 10 | U6: 6 | V6: 85 | W6: 77 | X6: 30 | Y6: 80 | Z6: 11 | AA6: 4 | AB6: 66 | AC6: A | AD6: 90 | AE6: 1 | AF6: 1 | AG6: 64 | AH6: B | AI6: 77 | AJ6: 33 | AK6: 24
A7: 大沥高中 | B7: 106班 | C7: 杨茱琳 | D7: 518 | E7: 5 | F7: 5 | G7: 284 | H7: 7 | I7: 6 | J7: 357 | K7: 6 | L7: 5 | M7: 478 | N7: 5 | O7: 5 | P7: 102 | Q7: 32 | R7: 13 | S7: 71 | T7: 31 | U7: 15 | V7: 111 | W7: 14 | X7: 9 | Y7: 73 | Z7: 48 | AA7: 24 | AB7: 55 | AC7: B | AD7: 82 | AE7: 21 | AF7: 12 | AG7: 66 | AH7: B | AI7: 79 | AJ7: 25 | AK7: 19
A8: 大沥高中 | B8: 106班 | C8: 汪梓盈 | D8: 511 | E8: 7 | F8: 6 | G8: 293 | H8: 3 | I8: 3 | J8: 356 | K8: 7 | L8: 6 | M8: 472 | N8: 6 | O8: 6 | P8: 107 | Q8: 10 | R8: 5 | S8: 94 | T8: 5 | U8: 3 | V8: 92 | W8: 49 | X8: 22 | Y8: 63 | Z8: 139 | AA8: 45 | AB8: 50 | AC8: B | AD8: 76 | AE8: 52 | AF8: 22 | AG8: 66 | AH8: B | AI8: 79 | AJ8: 25 | AK8: 19
A9: 大沥高中 | B9: 106班 | C9: 梁浚轩 | D9: 501 | E9: 11 | F9: 7 | G9: 259 | H9: 28 | I9: 14 | J9: 337 | K9: 22 | L9: 13 | M9: 463 | N9: 9 | O9: 7 | P9: 95 | Q9: 81 | R9: 32 | S9: 104 | T9: 2 | U9: 2 | V9: 60 | W9: 145 | X9: 47 | Y9: 78 | Z9: 18 | AA9: 8 | AB9: 52 | AC9: B | AD9: 78 | AE9: 39 | AF9: 17 | AG9: 74 | AH9: A | AI9: 86 | AJ9: 3 | AK9: 3
A10: 大沥高中 | B10: 106班 | C10: 刘诗晨 | D10: 497 | E10: 13 | F10: 8 | G10: 257 | H10: 31 | I10: 16 | J10: 330 | K10: 28 | L10: 15 | M10: 457 | N10: 15 | O10: 10 | P10: 100 | Q10: 42 | R10: 16 | S10: 69 | T10: 38 | U10: 16 | V10: 88 | W10: 69 | X10: 28 | Y10: 73 | Z10: 48 | AA10: 24 | AB10: 57 | AC10: A | AD10: 84 | AE10: 14 | AF10: 8 | AG10: 70 | AH10: A | AI10: 83 | AJ10: 12 | AK10: 10
A11: 大沥高中 | B11: 106班 | C11: 袁梓琦 | D11: 497 | E11: 13 | F11: 8 | G11: 269 | H11: 18 | I11: 10 | J11: 344 | K11: 12 | L11: 7 | M11: 459 | N11: 12 | O11: 8 | P11: 112 | Q11: 2 | R11: 2 | S11: 52 | T11: 81 | U11: 28 | V11: 105 | W11: 7 | X11: 2 | Y11: 75 | Z11: 38 | AA11: 19 | AB11: 45 | AC11: C | AD11: 70 | AE11: 99 | AF11: 37 | AG11: 70 | AH11: A | AI11: 83 | AJ11: 12 | AK11: 10
A12: 大沥高中 | B12: 106班 | C12: 张嘉铧 | D12: 497 | E12: 13 | F12: 8 | G12: 253 | H12: 40 | I12: 22 | J12: 327 | K12: 35 | L12: 19 | M12: 458 | N12: 14 | O12: 9 | P12: 91 | Q12: 109 | R12: 39 | S12: 43 | T12: 122 | U12: 40 | V12: 119 | W12: 2 | X12: 1 | Y12: 74 | Z12: 43 | AA12: 21 | AB12: 63 | AC12: A | AD12: 88 | AE12: 2 | AF12: 2 | AG12: 68 | AH12: B | AI12: 82 | AJ12: 16 | AK12: 12
A13: 大沥高中 | B13: 106班 | C13: 林思含 | D13: 495 | E13: 16 | F13: 11 | G13: 256 | H13: 34 | I13: 18 | J13: 330 | K13: 28 | L13: 15 | M13: 457 | N13: 15 | O13: 10 | P13: 86 | Q13: 143 | R13: 46 | S13: 85 | T13: 14 | U13: 9 | V13: 85 | W13: 77 | X13: 30 | Y13: 74 | Z13: 43 | AA13: 21 | AB13: 63 | AC13: A | AD13: 88 | AE13: 2 | AF13: 2 | AG13: 64 | AH13: B | AI13: 77 | AJ13: 33 | AK13: 24
A14: 大沥高中 | B14: 106班 | C14: 黄静雯 | D14: 493 | E14: 18 | F14: 12 | G14: 264 | H14: 22 | I14: 12 | J14: 342 | K14: 16 | L14: 11 | M14: 455 | N14: 18 | O14: 13 | P14: 99 | Q14: 48 | R14: 19 | S14: 83 | T14: 16 | U14: 11 | V14: 82 | W14: 87 | X14: 34 | Y14: 78 | Z14: 18 | AA14: 8 | AB14: 53 | AC14: B | AD14: 80 | AE14: 28 | AF14: 13 | AG14: 60 | AH14: B | AI14: 71 | AJ14: 53 | AK14: 37
... A56: 大沥高中 | B56: 106班 | C56: 刘益铭 | D56: 383 | E56: 163 | F56: 54 | G56: 208 | H56: 139 | I56: 49 | J56: 274 | K56: 139 | L56: 50 | M56: 356 | N56: 144 | O56: 53 | P56: 86 | Q56: 143 | R56: 46 | S56: 37 | T56: 141 | U56: 44 | V56: 85 | W56: 77 | X56: 30 | Y56: 66 | Z56: 116 | AA56: 39 | AB56: 26 | AC56: D | AD56: 43 | AE56: 193 | AF56: 54 | AG56: 56 | AH56: C | AI56: 66 | AJ56: 72 | AK56: 45
A57: 大沥高中 | B57: 106班 | C57: 谢凤仪 | D57: 缺考 | G57: 缺考 | J57: 缺考 | M57: 缺考 | P57: 缺考 | S57: 缺考 | V57: 缺考 | Y57: 缺考 | AB57: 缺考 | AG57: 缺考
A58: 大沥高中 | B58: 106班 | C58: 钟文海 | D58: 缺考 | G58: 缺考 | J58: 缺考 | M58: 缺考 | P58: 缺考 | S58: 缺考 | V58: 缺考 | Y58: 缺考 | AB58: 缺考 | AG58: 缺考

Sheet 总分排位
A1: 行政班 | B1: 姓名 | C1: 新高考原始总分 | E1: 新高考赋分总分 | G1: 新高考语数英总分 | I1: 新高考3+1总分
A2: 106班 | B2: 赖银婷 | C2: 516 | D2: 1 | E2: 556 | F2: 1 | G2: 307 | H2: 1 | I2: 390 | J2: 1
A3: 106班 | B3: 陈颖怡2 | C3: 499 | D3: 2 | E3: 538 | F3: 2 | G3: 304 | H3: 2 | I3: 372 | J3: 3
A4: 106班 | B4: 麦道奇 | C4: 494 | D4: 4 | E4: 535 | F4: 3 | G4: 292 | H4: 5 | I4: 370 | J4: 4
A5: 106班 | B5: 周楚莹 | C5: 497 | D5: 3 | E5: 534 | F5: 4 | G5: 287 | H5: 6 | I5: 367 | J5: 5
A6: 106班 | B6: 杨茱琳 | C6: 478 | D6: 5 | E6: 518 | F6: 5 | G6: 284 | H6: 7 | I6: 357 | J6: 6
A7: 106班 | B7: 汪梓盈 | C7: 472 | D7: 6 | E7: 511 | F7: 7 | G7: 293 | H7: 3 | I7: 356 | J7: 7
A8: 106班 | B8: 梁浚轩 | C8: 463 | D8: 9 | E8: 501 | F8: 11 | G8: 259 | H8: 28 | I8: 337 | J8: 22
A9: 106班 | B9: 袁梓琦 | C9: 459 | D9: 12 | E9: 497 | F9: 13 | G9: 269 | H9: 18 | I9: 344 | J9: 12
A10: 106班 | B10: 刘诗晨 | C10: 457 | D10: 15 | E10: 497 | F10: 13 | G10: 257 | H10: 31 | I10: 330 | J10: 28
A11: 106班 | B11: 张嘉铧 | C11: 458 | D11: 14 | E11: 497 | F11: 13 | G11: 253 | H11: 40 | I11: 327 | J11: 35
A12: 106班 | B12: 林思含 | C12: 457 | D12: 15 | E12: 495 | F12: 16 | G12: 256 | H12: 34 | I12: 330 | J12: 28
A13: 106班 | B13: 黄静雯 | C13: 455 | D13: 18 | E13: 493 | F13: 18 | G13: 264 | H13: 22 | I13: 342 | J13: 16
... A55: 106班 | B55: 刘益铭 | C55: 356 | D55: 144 | E55: 383 | F55: 163 | G55: 208 | H55: 139 | I55: 274 | J55: 139
C56: 分数 | D56: 校排 | E56: 分数 | F56: 校排 | G56: 分数 | H56: 校排 | I56: 分数 | J56: 校排

Sheet 单科排位
A1: 姓名 | B1: 语文 | D1: 数学 | F1: 外语 | H1: 历史 | J1: 政治 | N1: 地理
A2: 赖银婷 | B2: 104 | C2: 19 | D2: 106 | E2: 1 | F2: 97 | G2: 34 | H2: 83 | I2: 4 | J2: 58 | K2: A | L2: 84 | M2: 12 | N2: 68 | O2: B | P2: 82 | Q2: 16
A3: 陈颖怡2 | B3: 105 | C3: 17 | D3: 87 | E3: 11 | F3: 112 | G3: 11 | H3: 68 | I3: 94 | J3: 53 | K3: B | L3: 80 | M3: 28 | N3: 74 | O3: A | P3: 86 | Q3: 3
A4: 汪梓盈 | B4: 107 | C4: 10 | D4: 94 | E4: 5 | F4: 92 | G4: 49 | H4: 63 | I4: 139 | J4: 50 | K4: B | L4: 76 | M4: 52 | N4: 66 | O4: B | P4: 79 | Q4: 25
A5: 麦道奇 | B5: 109 | C5: 8 | D5: 65 | E5: 47 | F5: 118 | G5: 4 | H5: 78 | I5: 18 | J5: 56 | K5: A | L5: 83 | M5: 19 | N5: 68 | O5: B | P5: 82 | Q5: 16
A6: 周楚莹 | B6: 114 | C6: 1 | D6: 88 | E6: 10 | F6: 85 | G6: 77 | H6: 80 | I6: 11 | J6: 66 | K6: A | L6: 90 | M6: 1 | N6: 64 | O6: B | P6: 77 | Q6: 33
A7: 杨茱琳 | B7: 102 | C7: 32 | D7: 71 | E7: 31 | F7: 111 | G7: 14 | H7: 73 | I7: 48 | J7: 55 | K7: B | L7: 82 | M7: 21 | N7: 66 | O7: B | P7: 79 | Q7: 25
A8: 陈梓韵 | B8: 95 | C8: 81 | D8: 91 | E8: 8 | F8: 92 | G8: 49 | H8: 65 | I8: 123 | J8: 45 | K8: C | L8: 70 | M8: 99 | N8: 66 | O8: B | P8: 79 | Q8: 25
A9: 曾宪姿 | B9: 99 | C9: 48 | D9: 58 | E9: 65 | F9: 118 | G9: 4 | H9: 68 | I9: 94 | J9: 46 | K9: B | L9: 71 | M9: 87 | N9: 62 | O9: B | P9: 74 | Q9: 43
A10: 王雨 | B10: 97 | C10: 64 | D10: 73 | E10: 28 | F10: 101 | G10: 30 | H10: 68 | I10: 94 | J10: 50 | K10: B | L10: 76 | M10: 52 | N10: 60 | O10: B | P10: 71 | Q10: 53
A11: 袁梓琦 | B11: 112 | C11: 2 | D11: 52 | E11: 81 | F11: 105 | G11: 7 | H11: 75 | I11: 38 | J11: 45 | K11: C | L11: 70 | M11: 99 | N11: 70 | O11: A | P11: 83 | Q11: 12
A12: 杨海梵 | B12: 86 | C12: 143 | D12: 60 | E12: 58 | F12: 119 | G12: 2 | H12: 78 | I12: 18 | J12: 36 | K12: C | L12: 59 | M12: 168 | N12: 78 | O12: A | P12: 90 | Q12: 2
A13: 黄静雯 | B13: 99 | C13: 48 | D13: 83 | E13: 16 | F13: 82 | G13: 87 | H13: 78 | I13: 18 | J13: 53 | K13: B | L13: 80 | M13: 28 | N13: 60 | O13: B | P13: 71 | Q13: 53
... A55: 邵凯恒 | B55: 81 | C55: 171 | D55: 51 | E55: 88 | F55: 57 | G55: 153 | H55: 54 | I55: 183 | J55: 48 | K55: B | L55: 73 | M55: 68 | N55: 64 | O55: B | P55: 77 | Q55: 33
I56: =AVERAGE(I2:I55) -> 73.425926

Sheet 各小组排名分析
A1: 组别 | B1: 姓名 | C1: 学号 | D1: 总分 | E1: 六科 | F1: 三科 | G1: 四科 | H1: 语文 | I1: 数学 | J1: 外语 | K1: 历史 | L1: 政治 | M1: 地理 | N1: 浮动1 | O1: 浮动2 | P1: 三科 | Q1: 四科 | R1: 语文 | S1: 数学 | T1: 外语 | U1: 历史 | V1: 政治 | W1: 地理
A2: 1 | B2: 陈颖怡2 | C2: 10624 | D2: 538 | E2: =VLOOKUP(B2,总分排位!$B$2:$F$55,5,FALSE) -> 2 | F2: =VLOOKUP(B2,总分排位!$B$2:$F$55,5,FALSE) -> 2 | G2: =VLOOKUP(B2,总分排位!$B$2:$J$55,9,FALSE) -> 3 | H2: =VLOOKUP(B2,单科排位!$A$2:$C$55,3,FALSE) -> 17 | I2: =VLOOKUP(B2,单科排位!$A$2:$E$55,5,FALSE) -> 11 | J2: =VLOOKUP(B2,单科排位!$A$2:$G$55,7,FALSE) -> 11 | K2: =VLOOKUP(B2,单科排位!$A$2:$I$55,9,FALSE) -> 94 | L2: =VLOOKUP(B2,单科排位!$A$2:$M$55,13,FALSE) -> 28 | M2: =VLOOKUP(B2,单科排位!$A$2:$Q$55,17,FALSE) -> 3 | N2: 0 | O2: 3 | P2: =AVERAGE(F2:F8) -> 65.285714 | Q2: =AVERAGE(G2:G8) -> 67 | R2: =AVERAGE(H2:H8) -> 79.285714 | S2: =AVERAGE(I2:I8) -> 92.857143 | T2: =AVERAGE(J2:J8) -> 49.571429 | U2: =AVERAGE(K2:K8) -> 84.285714 | V2: =AVERAGE(L2:L8) -> 94.857143 | W2: =AVERAGE(M2:M8) -> 37.857143
B3: 肖明慧 | C3: 10647 | D3: 466 | E3: =VLOOKUP(B3,总分排位!$B$2:$F$55,5,FALSE) -> 43 | F3: =VLOOKUP(B3,总分排位!$B$2:$F$55,5,FALSE) -> 43 | G3: =VLOOKUP(B3,总分排位!$B$2:$J$55,9,FALSE) -> 41 | H3: =VLOOKUP(B3,单科排位!$A$2:$C$55,3,FALSE) -> 38 | I3: =VLOOKUP(B3,单科排位!$A$2:$E$55,5,FALSE) -> 81 | J3: =VLOOKUP(B3,单科排位!$A$2:$G$55,7,FALSE) -> 55 | K3: =VLOOKUP(B3,单科排位!$A$2:$I$55,9,FALSE) -> 15 | L3: =VLOOKUP(B3,单科排位!$A$2:$M$55,13,FALSE) -> 99 | M3: =VLOOKUP(B3,单科排位!$A$2:$Q$55,17,FALSE) -> 43 | N3: 9 | O3: -6
B4: 曾婷婷 | C4: 10619 | D4: 459 | E4: =VLOOKUP(B4,总分排位!$B$2:$F$55,5,FALSE) -> 51 | F4: =VLOOKUP(B4,总分排位!$B$2:$F$55,5,FALSE) -> 51 | G4: =VLOOKUP(B4,总分排位!$B$2:$J$55,9,FALSE) -> 83 | H4: =VLOOKUP(B4,单科排位!$A$2:$C$55,3,FALSE) -> 64 | I4: =VLOOKUP(B4,单科排位!$A$2:$E$55,5,FALSE) -> 70 | J4: =VLOOKUP(B4,单科排位!$A$2:$G$55,7,FALSE) -> 106 | K4: =VLOOKUP(B4,单科排位!$A$2:$I$55,9,FALSE) -> 63 | L4: =VLOOKUP(B4,单科排位!$A$2:$M$55,13,FALSE) -> 41 | M4: =VLOOKUP(B4,单科排位!$A$2:$Q$55,17,FALSE) -> 16 | N4: -23 | O4: -15
B5: 刘益铭 | C5: 10607 | D5: 383 | E5: =VLOOKUP(B5,总分排位!$B$2:$F$55,5,FALSE) -> 163 | F5: =VLOOKUP(B5,总分排位!$B$2:$F$55,5,FALSE) -> 163 | G5: =VLOOKUP(B5,总分排位!$B$2:$J$55,9,FALSE) -> 139 | H5: =VLOOKUP(B5,单科排位!$A$2:$C$55,3,FALSE) -> 143 | I5: =VLOOKUP(B5,单科排位!$A$2:$E$55,5,FALSE) -> 141 | J5: =VLOOKUP(B5,单科排位!$A$2:$G$55,7,FALSE) -> 77 | K5: =VLOOKUP(B5,单科排位!$A$2:$I$55,9,FALSE) -> 116 | L5: =VLOOKUP(B5,单科排位!$A$2:$M$55,13,FALSE) -> 193 | M5: =VLOOKUP(B5,单科排位!$A$2:$Q$55,17,FALSE) -> 72 | N5: -65 | O5: -88
B6: 郭恩榆 | C6: 10628 | D6: 449 | E6: =VLOOKUP(B6,总分排位!$B$2:$F$55,5,FALSE) -> 67 | F6: =VLOOKUP(B6,总分排位!$B$2:$F$55,5,FALSE) -> 67 | G6: =VLOOKUP(B6,总分排位!$B$2:$J$55,9,FALSE) -> 59 | H6: =VLOOKUP(B6,单科排位!$A$2:$C$55,3,FALSE) -> 164 | I6: =VLOOKUP(B6,单科排位!$A$2:$E$55,5,FALSE) -> 56 | J6: =VLOOKUP(B6,单科排位!$A$2:$G$55,7,FALSE) -> 22 | K6: =VLOOKUP(B6,单科排位!$A$2:$I$55,9,FALSE) -> 160 | L6: =VLOOKUP(B6,单科排位!$A$2:$M$55,13,FALSE) -> 76 | M6: =VLOOKUP(B6,单科排位!$A$2:$Q$55,17,FALSE) -> 72 | N6: -19 | O6: -10
B7: 陈庆旭 | C7: 10602 | D7: 442 | E7: =VLOOKUP(B7,总分排位!$B$2:$F$55,5,FALSE) -> 81 | F7: =VLOOKUP(B7,总分排位!$B$2:$F$55,5,FALSE) -> 81 | G7: =VLOOKUP(B7,总分排位!$B$2:$J$55,9,FALSE) -> 92 | H7: =VLOOKUP(B7,单科排位!$A$2:$C$55,3,FALSE) -> 127 | I7: =VLOOKUP(B7,单科排位!$A$2:$E$55,5,FALSE) -> 173 | J7: =VLOOKUP(B7,单科排位!$A$2:$G$55,7,FALSE) -> 21 | K7: =VLOOKUP(B7,单科排位!$A$2:$I$55,9,FALSE) -> 71 | L7: =VLOOKUP(B7,单科排位!$A$2:$M$55,13,FALSE) -> 128 | M7: =VLOOKUP(B7,单科排位!$A$2:$Q$55,17,FALSE) -> 16 | N7: -9 | O7: 26
B8: 区健仪 | C8: 10643 | D8: 460 | E8: =VLOOKUP(B8,总分排位!$B$2:$F$55,5,FALSE) -> 50 | F8: =VLOOKUP(B8,总分排位!$B$2:$F$55,5,FALSE) -> 50 | G8: =VLOOKUP(B8,总分排位!$B$2:$J$55,9,FALSE) -> 52 | H8: =VLOOKUP(B8,单科排位!$A$2:$C$55,3,FALSE) -> 2 | I8: =VLOOKUP(B8,单科排位!$A$2:$E$55,5,FALSE) -> 118 | J8: =VLOOKUP(B8,单科排位!$A$2:$G$55,7,FALSE) -> 55 | K8: =VLOOKUP(B8,单科排位!$A$2:$I$55,9,FALSE) -> 71 | L8: =VLOOKUP(B8,单科排位!$A$2:$M$55,13,FALSE) -> 99 | M8: =VLOOKUP(B8,单科排位!$A$2:$Q$55,17,FALSE) -> 43 | N8: 41 | O8: 30
A9: 2 | B9: 朱鹏博 | C9: 10618 | D9: 491 | E9: =VLOOKUP(B9,总分排位!$B$2:$F$55,5,FALSE) -> 21 | F9: =VLOOKUP(B9,总分排位!$B$2:$F$55,5,FALSE) -> 21 | G9: =VLOOKUP(B9,总分排位!$B$2:$J$55,9,FALSE) -> 38 | H9: =VLOOKUP(B9,单科排位!$A$2:$C$55,3,FALSE) -> 143 | I9: =VLOOKUP(B9,单科排位!$A$2:$E$55,5,FALSE) -> 129 | J9: =VLOOKUP(B9,单科排位!$A$2:$G$55,7,FALSE) -> 4 | K9: =VLOOKUP(B9,单科排位!$A$2:$I$55,9,FALSE) -> 8 | L9: =VLOOKUP(B9,单科排位!$A$2:$M$55,13,FALSE) -> 28 | M9: =VLOOKUP(B9,单科排位!$A$2:$Q$55,17,FALSE) -> 8 | N9: -50 | O9: -2 | P9: =AVERAGE(F9:F14) -> 49.5 | Q9: =AVERAGE(G9:G14) -> 48.333333 | R9: =AVERAGE(H9:H14) -> 84.666667 | S9: =AVERAGE(I9:I14) -> 84.333333 | T9: =AVERAGE(J9:J14) -> 34.166667 | U9: =AVERAGE(K9:K14) -> 59 | V9: =AVERAGE(L9:L14) -> 95.666667 | W9: =AVERAGE(M9:M14) -> 29
B10: 周楚莹 | C10: 10655 | D10: 534 | E10: =VLOOKUP(B10,总分排位!$B$2:$F$55,5,FALSE) -> 4 | F10: =VLOOKUP(B10,总分排位!$B$2:$F$55,5,FALSE) -> 4 | G10: =VLOOKUP(B10,总分排位!$B$2:$J$55,9,FALSE) -> 5 | H10: =VLOOKUP(B10,单科排位!$A$2:$C$55,3,FALSE) -> 1 | I10: =VLOOKUP(B10,单科排位!$A$2:$E$55,5,FALSE) -> 10 | J10: =VLOOKUP(B10,单科排位!$A$2:$G$55,7,FALSE) -> 77 | K10: =VLOOKUP(B10,单科排位!$A$2:$I$55,9,FALSE) -> 11 | L10: =VLOOKUP(B10,单科排位!$A$2:$M$55,13,FALSE) -> 1 | M10: =VLOOKUP(B10,单科排位!$A$2:$Q$55,17,FALSE) -> 33 | N10: 3 | O10: 9
B11: 曾宪姿 | C11: 10620 | D11: 488 | E11: =VLOOKUP(B11,总分排位!$B$2:$F$55,5,FALSE) -> 26 | F11: =VLOOKUP(B11,总分排位!$B$2:$F$55,5,FALSE) -> 26 | G11: =VLOOKUP(B11,总分排位!$B$2:$J$55,9,FALSE) -> 13 | H11: =VLOOKUP(B11,单科排位!$A$2:$C$55,3,FALSE) -> 48 | I11: =VLOOKUP(B11,单科排位!$A$2:$E$55,5,FALSE) -> 65 | J11: =VLOOKUP(B11,单科排位!$A$2:$G$55,7,FALSE) -> 4 | K11: =VLOOKUP(B11,单科排位!$A$2:$I$55,9,FALSE) -> 94 | L11: =VLOOKUP(B11,单科排位!$A$2:$M$55,13,FALSE) -> 87 | M11: =VLOOKUP(B11,单科排位!$A$2:$Q$55,17,FALSE) -> 43 | N11: -19 | O11: 1
B12: 杨海梵 | C12: 10615 | D12: 492 | E12: =VLOOKUP(B12,总分排位!$B$2:$F$55,5,FALSE) -> 19 | F12: =VLOOKUP(B12,总分排位!$B$2:$F$55,5,FALSE) -> 19 | G12: =VLOOKUP(B12,总分排位!$B$2:$J$55,9,FALSE) -> 13 | H12: =VLOOKUP(B12,单科排位!$A$2:$C$55,3,FALSE) -> 143 | I12: =VLOOKUP(B12,单科排位!$A$2:$E$55,5,FALSE) -> 58 | J12: =VLOOKUP(B12,单科排位!$A$2:$G$55,7,FALSE) -> 2 | K12: =VLOOKUP(B12,单科排位!$A$2:$I$55,9,FALSE) -> 18 | L12: =VLOOKUP(B12,单科排位!$A$2:$M$55,13,FALSE) -> 168 | M12: =VLOOKUP(B12,单科排位!$A$2:$Q$55,17,FALSE) -> 2 | N12: -6 | O12: -5
B13: 邓依梵 | C13: 10626 | D13: 418 | E13: =VLOOKUP(B13,总分排位!$B$2:$F$55,5,FALSE) -> 122 | F13: =VLOOKUP(B13,总分排位!$B$2:$F$55,5,FALSE) -> 122 | G13: =VLOOKUP(B13,总分排位!$B$2:$J$55,9,FALSE) -> 100 | H13: =VLOOKUP(B13,单科排位!$A$2:$C$55,3,FALSE) -> 64 | I13: =VLOOKUP(B13,单科排位!$A$2:$E$55,5,FALSE) -> 156 | J13: =VLOOKUP(B13,单科排位!$A$2:$G$55,7,FALSE) -> 11 | K13: =VLOOKUP(B13,单科排位!$A$2:$I$55,9,FALSE) -> 116 | L13: =VLOOKUP(B13,单科排位!$A$2:$M$55,13,FALSE) -> 113 | M13: =VLOOKUP(B13,单科排位!$A$2:$Q$55,17,FALSE) -> 87 | N13: -2 | O13: -61
B14: 简芷晴 | C14: 10633 | D14: 431 | E14: =VLOOKUP(B14,总分排位!$B$2:$F$55,5,FALSE) -> 105 | F14: =VLOOKUP(B14,总分排位!$B$2:$F$55,5,FALSE) -> 105 | G14: =VLOOKUP(B14,总分排位!$B$2:$J$55,9,FALSE) -> 121 | H14: =VLOOKUP(B14,单科排位!$A$2:$C$55,3,FALSE) -> 109 | I14: =VLOOKUP(B14,单科排位!$A$2:$E$55,5,FALSE) -> 88 | J14: =VLOOKUP(B14,单科排位!$A$2:$G$55,7,FALSE) -> 107 | K14: =VLOOKUP(B14,单科排位!$A$2:$I$55,9,FALSE) -> 107 | L14: =VLOOKUP(B14,单科排位!$A$2:$M$55,13,FALSE) -> 177 | M14: =VLOOKUP(B14,单科排位!$A$2:$Q$55,17,FALSE) -> 1 | N14: -33 | O14: -5
A15: 3 | B15: 林思含 | C15: 10636 | D15: 495 | E15: =VLOOKUP(B15,总分排位!$B$2:$F$55,5,FALSE) -> 16 | F15: =VLOOKUP(B15,总分排位!$B$2:$F$55,5,FALSE) -> 16 | G15: =VLOOKUP(B15,总分排位!$B$2:$J$55,9,FALSE) -> 28 | H15: =VLOOKUP(B15,单科排位!$A$2:$C$55,3,FALSE) -> 143 | I15: =VLOOKUP(B15,单科排位!$A$2:$E$55,5,FALSE) -> 14 | J15: =VLOOKUP(B15,单科排位!$A$2:$G$55,7,FALSE) -> 77 | K15: =VLOOKUP(B15,单科排位!$A$2:$I$55,9,FALSE) -> 43 | L15: =VLOOKUP(B15,单科排位!$A$2:$M$55,13,FALSE) -> 2 | M15: =VLOOKUP(B15,单科排位!$A$2:$Q$55,17,FALSE) -> 33 | N15: -20 | O15: -10 | P15: =AVERAGE(F15:F20) -> 52 | Q15: =AVERAGE(G15:G20) -> 59.166667 | R15: =AVERAGE(H15:H20) -> 76.833333 | S15: =AVERAGE(I15:I20) -> 49.166667 | T15: =AVERAGE(J15:J20) -> 101.33333 | U15: =AVERAGE(K15:K20) -> 48 | V15: =AVERAGE(L15:L20) -> 62.333333 | W15: =AVERAGE(M15:M20) -> 44.166667
B16: 邹贝思 | C16: 10656 | D16: 454 | E16: =VLOOKUP(B16,总分排位!$B$2:$F$55,5,FALSE) -> 56 | F16: =VLOOKUP(B16,总分排位!$B$2:$F$55,5,FALSE) -> 56 | G16: =VLOOKUP(B16,总分排位!$B$2:$J$55,9,FALSE) -> 83 | H16: =VLOOKUP(B16,单科排位!$A$2:$C$55,3,FALSE) -> 73 | I16: =VLOOKUP(B16,单科排位!$A$2:$E$55,5,FALSE) -> 42 | J16: =VLOOKUP(B16,单科排位!$A$2:$G$55,7,FALSE) -> 118 | K16: =VLOOKUP(B16,单科排位!$A$2:$I$55,9,FALSE) -> 94 | L16: =VLOOKUP(B16,单科排位!$A$2:$M$55,13,FALSE) -> 41 | M16: =VLOOKUP(B16,单科排位!$A$2:$Q$55,17,FALSE) -> 33 | N16: 51 | O16: 8
B17: 黄静雯 | C17: 10631 | D17: 493 | E17: =VLOOKUP(B17,总分排位!$B$2:$F$55,5,FALSE) -> 18 | F17: =VLOOKUP(B17,总分排位!$B$2:$F$55,5,FALSE) -> 18 | G17: =VLOOKUP(B17,总分排位!$B$2:$J$55,9,FALSE) -> 16 | H17: =VLOOKUP(B17,单科排位!$A$2:$C$55,3,FALSE) -> 48 | I17: =VLOOKUP(B17,单科排位!$A$2:$E$55,5,FALSE) -> 16 | J17: =VLOOKUP(B17,单科排位!$A$2:$G$55,7,FALSE) -> 87 | K17: =VLOOKUP(B17,单科排位!$A$2:$I$55,9,FALSE) -> 18 | L17: =VLOOKUP(B17,单科排位!$A$2:$M$55,13,FALSE) -> 28 | M17: =VLOOKUP(B17,单科排位!$A$2:$Q$55,17,FALSE) -> 53 | N17: 51 | O17: 59
B18: 何家恩 | C18: 10630 | D18: 472 | E18: =VLOOKUP(B18,总分排位!$B$2:$F$55,5,FALSE) -> 36 | F18: =VLOOKUP(B18,总分排位!$B$2:$F$55,5,FALSE) -> 36 | G18: =VLOOKUP(B18,总分排位!$B$2:$J$55,9,FALSE) -> 28 | H18: =VLOOKUP(B18,单科排位!$A$2:$C$55,3,FALSE) -> 42 | I18: =VLOOKUP(B18,单科排位!$A$2:$E$55,5,FALSE) -> 6 | J18: =VLOOKUP(B18,单科排位!$A$2:$G$55,7,FALSE) -> 121 | K18: =VLOOKUP(B18,单科排位!$A$2:$I$55,9,FALSE) -> 83 | L18: =VLOOKUP(B18,单科排位!$A$2:$M$55,13,FALSE) -> 76 | M18: =VLOOKUP(B18,单科排位!$A$2:$Q$55,17,FALSE) -> 60 | N18: -11 | O18: 29
B19: 谈博轩 | C19: 10611 | D19: 454 | E19: =VLOOKUP(B19,总分排位!$B$2:$F$55,5,FALSE) -> 56 | F19: =VLOOKUP(B19,总分排位!$B$2:$F$55,5,FALSE) -> 56 | G19: =VLOOKUP(B19,总分排位!$B$2:$J$55,9,FALSE) -> 61 | H19: =VLOOKUP(B19,单科排位!$A$2:$C$55,3,FALSE) -> 91 | I19: =VLOOKUP(B19,单科排位!$A$2:$E$55,5,FALSE) -> 88 | J19: =VLOOKUP(B19,单科排位!$A$2:$G$55,7,FALSE) -> 55 | K19: =VLOOKUP(B19,单科排位!$A$2:$I$55,9,FALSE) -> 32 | L19: =VLOOKUP(B19,单科排位!$A$2:$M$55,13,FALSE) -> 99 | M19: =VLOOKUP(B19,单科排位!$A$2:$Q$55,17,FALSE) -> 43 | N19: -77 | O19: 38
B20: 谭伟乔 | C20: 10612 | D20: 414 | E20: =VLOOKUP(B20,总分排位!$B$2:$F$55,5,FALSE) -> 130 | F20: =VLOOKUP(B20,总分排位!$B$2:$F$55,5,FALSE) -> 130 | G20: =VLOOKUP(B20,总分排位!$B$2:$J$55,9,FALSE) -> 139 | H20: =VLOOKUP(B20,单科排位!$A$2:$C$55,3,FALSE) -> 64 | I20: =VLOOKUP(B20,单科排位!$A$2:$E$55,5,FALSE) -> 129 | J20: =VLOOKUP(B20,单科排位!$A$2:$G$55,7,FALSE) -> 150 | K20: =VLOOKUP(B20,单科排位!$A$2:$I$55,9,FALSE) -> 18 | L20: =VLOOKUP(B20,单科排位!$A$2:$M$55,13,FALSE) -> 128 | M20: =VLOOKUP(B20,单科排位!$A$2:$Q$55,17,FALSE) -> 43 | N20: 0 | O20: 0
A21: 4 | B21: 麦道奇 | C21: 10608 | D21: 535 | E21: =VLOOKUP(B21,总分排位!$B$2:$F$55,5,FALSE) -> 3 | F21: =VLOOKUP(B21,总分排位!$B$2:$F$55,5,FALSE) -> 3 | G21: =VLOOKUP(B21,总分排位!$B$2:$J$55,9,FALSE) -> 4 | H21: =VLOOKUP(B21,单科排位!$A$2:$C$55,3,FALSE) -> 8 | I21: =VLOOKUP(B21,单科排位!$A$2:$E$55,5,FALSE) -> 47 | J21: =VLOOKUP(B21,单科排位!$A$2:$G$55,7,FALSE) -> 4 | K21: =VLOOKUP(B21,单科排位!$A$2:$I$55,9,FALSE) -> 18 | L21: =VLOOKUP(B21,单科排位!$A$2:$M$55,13,FALSE) -> 19 | M21: =VLOOKUP(B21,单科排位!$A$2:$Q$55,17,FALSE) -> 16 | N21: -212 | O21: 1 | P21: =AVERAGE(F21:F26) -> 21.6 | Q21: =AVERAGE(G2:G57) -> 60.722222 | R21: =AVERAGE(H21:H25) -> 52 | S21: =AVERAGE(I21:I26) -> 47.6 | T21: =AVERAGE(J21:J26) -> 49.8 | U21: =AVERAGE(K21:K26) -> 60 | V21: =AVERAGE(L21:L26) -> 38.6 | W21: =AVERAGE(M21:M26) -> 35.2
B22: 汪梓盈 | C22: 10644 | D22: 511 | E22: =VLOOKUP(B22,总分排位!$B$2:$F$55,5,FALSE) -> 7 | F22: =VLOOKUP(B22,总分排位!$B$2:$F$55,5,FALSE) -> 7 | G22: =VLOOKUP(B22,总分排位!$B$2:$J$55,9,FALSE) -> 7 | H22: =VLOOKUP(B22,单科排位!$A$2:$C$55,3,FALSE) -> 10 | I22: =VLOOKUP(B22,单科排位!$A$2:$E$55,5,FALSE) -> 5 | J22: =VLOOKUP(B22,单科排位!$A$2:$G$55,7,FALSE) -> 49 | K22: =VLOOKUP(B22,单科排位!$A$2:$I$55,9,FALSE) -> 139 | L22: =VLOOKUP(B22,单科排位!$A$2:$M$55,13,FALSE) -> 52 | M22: =VLOOKUP(B22,单科排位!$A$2:$Q$55,17,FALSE) -> 25 | N22: 4 | O22: 9
B23: 梁浚轩 | C23: 10606 | D23: 501 | E23: =VLOOKUP(B23,总分排位!$B$2:$F$55,5,FALSE) -> 11 | F23: =VLOOKUP(B23,总分排位!$B$2:$F$55,5,FALSE) -> 11 | G23: =VLOOKUP(B23,总分排位!$B$2:$J$55,9,FALSE) -> 22 | H23: =VLOOKUP(B23,单科排位!$A$2:$C$55,3,FALSE) -> 81 | I23: =VLOOKUP(B23,单科排位!$A$2:$E$55,5,FALSE) -> 2 | J23: =VLOOKUP(B23,单科排位!$A$2:$G$55,7,FALSE) -> 145 | K23: =VLOOKUP(B23,单科排位!$A$2:$I$55,9,FALSE) -> 18 | L23: =VLOOKUP(B23,单科排位!$A$2:$M$55,13,FALSE) -> 39 | M23: =VLOOKUP(B23,单科排位!$A$2:$Q$55,17,FALSE) -> 3 | N23: -1 | O23: 38
B24: 吕柯鋆 | C24: 10640 | D24: 469 | E24: =VLOOKUP(B24,总分排位!$B$2:$F$55,5,FALSE) -> 38 | F24: =VLOOKUP(B24,总分排位!$B$2:$F$55,5,FALSE) -> 38 | G24: =VLOOKUP(B24,总分排位!$B$2:$J$55,9,FALSE) -> 48 | H24: =VLOOKUP(B24,单科排位!$A$2:$C$55,3,FALSE) -> 109 | I24: =VLOOKUP(B24,单科排位!$A$2:$E$55,5,FALSE) -> 106 | J24: =VLOOKUP(B24,单科排位!$A$2:$G$55,7,FALSE) -> 8 | K24: =VLOOKUP(B24,单科排位!$A$2:$I$55,9,FALSE) -> 107 | L24: =VLOOKUP(B24,单科排位!$A$2:$M$55,13,FALSE) -> 7 | M24: =VLOOKUP(B24,单科排位!$A$2:$Q$55,17,FALSE) -> 72 | N24: -75 | O24: -5
B25: 谢凤仪 | C25: 10648 | N25: 15
B26: 刘友连 | C26: 10639 | D26: 461 | E26: =VLOOKUP(B26,总分排位!$B$2:$F$55,5,FALSE) -> 49 | F26: =VLOOKUP(B26,总分排位!$B$2:$F$55,5,FALSE) -> 49 | G26: =VLOOKUP(B26,总分排位!$B$2:$J$55,9,FALSE) -> 45 | H26: =VLOOKUP(B26,单科排位!$A$2:$C$55,3,FALSE) -> 87 | I26: =VLOOKUP(B26,单科排位!$A$2:$E$55,5,FALSE) -> 78 | J26: =VLOOKUP(B26,单科排位!$A$2:$G$55,7,FALSE) -> 43 | K26: =VLOOKUP(B26,单科排位!$A$2:$I$55,9,FALSE) -> 18 | L26: =VLOOKUP(B26,单科排位!$A$2:$M$55,13,FALSE) -> 76 | M26: =VLOOKUP(B26,单科排位!$A$2:$Q$55,17,FALSE) -> 60 | N26: -71 | O26: 2
A27: 5 | B27: 徐志慧 | C27: 10649 | D27: 482 | E27: =VLOOKUP(B27,总分排位!$B$2:$F$55,5,FALSE) -> 30 | F27: =VLOOKUP(B27,总分排位!$B$2:$F$55,5,FALSE) -> 30 | G27: =VLOOKUP(B27,总分排位!$B$2:$J$55,9,FALSE) -> 45 | H27: =VLOOKUP(B27,单科排位!$A$2:$C$55,3,FALSE) -> 99 | I27: =VLOOKUP(B27,单科排位!$A$2:$E$55,5,FALSE) -> 135 | J27: =VLOOKUP(B27,单科排位!$A$2:$G$55,7,FALSE) -> 7 | K27: =VLOOKUP(B27,单科排位!$A$2:$I$55,9,FALSE) -> 63 | L27: =VLOOKUP(B27,单科排位!$A$2:$M$55,13,FALSE) -> 14 | M27: =VLOOKUP(B27,单科排位!$A$2:$Q$55,17,FALSE) -> 25 | N27: -41 | O27: -18 | P27: =AVERAGE(F27:F33) -> 71.857143 | Q27: =AVERAGE(G27:G33) -> 82.428571 | R27: =AVERAGE(H27:H33) -> 55.857143 | S27: =AVERAGE(I27:I33) -> 95.142857 | T27: =AVERAGE(J27:J33) -> 79.857143 | U27: =AVERAGE(K27:K33) -> 89.142857 | V27: =AVERAGE(L27:L33) -> 71.714286 | W27: =AVERAGE(M27:M33) -> 40.857143
B28: 余翠仪 | C28: 10651 | D28: 449 | E28: =VLOOKUP(B28,总分排位!$B$2:$F$55,5,FALSE) -> 67 | F28: =VLOOKUP(B28,总分排位!$B$2:$F$55,5,FALSE) -> 67 | G28: =VLOOKUP(B28,总分排位!$B$2:$J$55,9,FALSE) -> 48 | H28: =VLOOKUP(B28,单科排位!$A$2:$C$55,3,FALSE) -> 19 | I28: =VLOOKUP(B28,单科排位!$A$2:$E$55,5,FALSE) -> 99 | J28: =VLOOKUP(B28,单科排位!$A$2:$G$55,7,FALSE) -> 25 | K28: =VLOOKUP(B28,单科排位!$A$2:$I$55,9,FALSE) -> 139 | L28: =VLOOKUP(B28,单科排位!$A$2:$M$55,13,FALSE) -> 156 | M28: =VLOOKUP(B28,单科排位!$A$2:$Q$55,17,FALSE) -> 60 | N28: -37 | O28: -45
B29: 李彤彤 | C29: 10635 | D29: 441 | E29: =VLOOKUP(B29,总分排位!$B$2:$F$55,5,FALSE) -> 83 | F29: =VLOOKUP(B29,总分排位!$B$2:$F$55,5,FALSE) -> 83 | G29: =VLOOKUP(B29,总分排位!$B$2:$J$55,9,FALSE) -> 129 | H29: =VLOOKUP(B29,单科排位!$A$2:$C$55,3,FALSE) -> 55 | I29: =VLOOKUP(B29,单科排位!$A$2:$E$55,5,FALSE) -> 88 | J29: =VLOOKUP(B29,单科排位!$A$2:$G$55,7,FALSE) -> 163 | K29: =VLOOKUP(B29,单科排位!$A$2:$I$55,9,FALSE) -> 15 | L29: =VLOOKUP(B29,单科排位!$A$2:$M$55,13,FALSE) -> 5 | M29: =VLOOKUP(B29,单科排位!$A$2:$Q$55,17,FALSE) -> 43 | N29: -15 | O29: -28
B30: 袁梓琦 | C30: 10652 | D30: 497 | E30: =VLOOKUP(B30,总分排位!$B$2:$F$55,5,FALSE) -> 13 | F30: =VLOOKUP(B30,总分排位!$B$2:$F$55,5,FALSE) -> 13 | G30: =VLOOKUP(B30,总分排位!$B$2:$J$55,9,FALSE) -> 12 | H30: =VLOOKUP(B30,单科排位!$A$2:$C$55,3,FALSE) -> 2 | I30: =VLOOKUP(B30,单科排位!$A$2:$E$55,5,FALSE) -> 81 | J30: =VLOOKUP(B30,单科排位!$A$2:$G$55,7,FALSE) -> 7 | K30: =VLOOKUP(B30,单科排位!$A$2:$I$55,9,FALSE) -> 38 | L30: =VLOOKUP(B30,单科排位!$A$2:$M$55,13,FALSE) -> 99 | M30: =VLOOKUP(B30,单科排位!$A$2:$Q$55,17,FALSE) -> 12 | N30: -31 | O30: 22
B31: 邵凯恒 | C31: 10610 | D31: 393 | E31: =VLOOKUP(B31,总分排位!$B$2:$F$55,5,FALSE) -> 153 | F31: =VLOOKUP(B31,总分排位!$B$2:$F$55,5,FALSE) -> 153 | G31: =VLOOKUP(B31,总分排位!$B$2:$J$55,9,FALSE) -> 178 | H31: =VLOOKUP(B31,单科排位!$A$2:$C$55,3,FALSE) -> 171 | I31: =VLOOKUP(B31,单科排位!$A$2:$E$55,5,FALSE) -> 88 | J31: =VLOOKUP(B31,单科排位!$A$2:$G$55,7,FALSE) -> 153 | K31: =VLOOKUP(B31,单科排位!$A$2:$I$55,9,FALSE) -> 183 | L31: =VLOOKUP(B31,单科排位!$A$2:$M$55,13,FALSE) -> 68 | M31: =VLOOKUP(B31,单科排位!$A$2:$Q$55,17,FALSE) -> 33 | N31: -65 | O31: -31
B32: 谢俊昌 | C32: 10614 | D32: 440 | E32: =VLOOKUP(B32,总分排位!$B$2:$F$55,5,FALSE) -> 84 | F32: =VLOOKUP(B32,总分排位!$B$2:$F$55,5,FALSE) -> 84 | G32: =VLOOKUP(B32,总分排位!$B$2:$J$55,9,FALSE) -> 95 | H32: =VLOOKUP(B32,单科排位!$A$2:$C$55,3,FALSE) -> 13 | I32: =VLOOKUP(B32,单科排位!$A$2:$E$55,5,FALSE) -> 99 | J32: =VLOOKUP(B32,单科排位!$A$2:$G$55,7,FALSE) -> 102 | K32: =VLOOKUP(B32,单科排位!$A$2:$I$55,9,FALSE) -> 148 | L32: =VLOOKUP(B32,单科排位!$A$2:$M$55,13,FALSE) -> 41 | M32: =VLOOKUP(B32,单科排位!$A$2:$Q$55,17,FALSE) -> 53 | N32: 0 | O32: -3
B33: 林烨叶 | C33: 10637 | D33: 445 | E33: =VLOOKUP(B33,总分排位!$B$2:$F$55,5,FALSE) -> 73 | F33: =VLOOKUP(B33,总分排位!$B$2:$F$55,5,FALSE) -> 73 | G33: =VLOOKUP(B33,总分排位!$B$2:$J$55,9,FALSE) -> 70 | H33: =VLOOKUP(B33,单科排位!$A$2:$C$55,3,FALSE) -> 32 | I33: =VLOOKUP(B33,单科排位!$A$2:$E$55,5,FALSE) -> 76 | J33: =VLOOKUP(B33,单科排位!$A$2:$G$55,7,FALSE) -> 102 | K33: =VLOOKUP(B33,单科排位!$A$2:$I$55,9,FALSE) -> 38 | L33: =VLOOKUP(B33,单科排位!$A$2:$M$55,13,FALSE) -> 119 | M33: =VLOOKUP(B33,单科排位!$A$2:$Q$55,17,FALSE) -> 60 | N33: -61 | O33: 9
A34: 6 | B34: 陈梓韵 | C34: 10625 | D34: 492 | E34: =VLOOKUP(B34,总分排位!$B$2:$F$55,5,FALSE) -> 19 | F34: =VLOOKUP(B34,总分排位!$B$2:$F$55,5,FALSE) -> 19 | G34: =VLOOKUP(B34,总分排位!$B$2:$J$55,9,FALSE) -> 13 | H34: =VLOOKUP(B34,单科排位!$A$2:$C$55,3,FALSE) -> 81 | I34: =VLOOKUP(B34,单科排位!$A$2:$E$55,5,FALSE) -> 8 | J34: =VLOOKUP(B34,单科排位!$A$2:$G$55,7,FALSE) -> 49 | K34: =VLOOKUP(B34,单科排位!$A$2:$I$55,9,FALSE) -> 123 | L34: =VLOOKUP(B34,单科排位!$A$2:$M$55,13,FALSE) -> 99 | M34: =VLOOKUP(B34,单科排位!$A$2:$Q$55,17,FALSE) -> 25 | N34: -15 | O34: -1 | P34: =AVERAGE(F34:F39) -> 66.4 | Q34: =AVERAGE(G34:G39) -> 64.4 | R34: =AVERAGE(H34:H39) -> 56.8 | S34: =AVERAGE(I34:I39) -> 77.6 | T34: =AVERAGE(J34:J39) -> 76 | U34: =AVERAGE(K34:K39) -> 95.2 | V34: =AVERAGE(L34:L39) -> 100.4 | W34: =AVERAGE(M34:M39) -> 28.6
B35: 钟文海 | C35: 10617 | N35: -3
B36: 张媛琪 | C36: 10654 | D36: 437 | E36: =VLOOKUP(B36,总分排位!$B$2:$F$55,5,FALSE) -> 95 | F36: =VLOOKUP(B36,总分排位!$B$2:$F$55,5,FALSE) -> 95 | G36: =VLOOKUP(B36,总分排位!$B$2:$J$55,9,FALSE) -> 100 | H36: =VLOOKUP(B36,单科排位!$A$2:$C$55,3,FALSE) -> 55 | I36: =VLOOKUP(B36,单科排位!$A$2:$E$55,5,FALSE) -> 156 | J36: =VLOOKUP(B36,单科排位!$A$2:$G$55,7,FALSE) -> 30 | K36: =VLOOKUP(B36,单科排位!$A$2:$I$55,9,FALSE) -> 171 | L36: =VLOOKUP(B36,单科排位!$A$2:$M$55,13,FALSE) -> 156 | M36: =VLOOKUP(B36,单科排位!$A$2:$Q$55,17,FALSE) -> 3 | N36: -18 | O36: -37
B37: 麦晓勤 | C37: 10609 | D37: 431 | E37: =VLOOKUP(B37,总分排位!$B$2:$F$55,5,FALSE) -> 105 | F37: =VLOOKUP(B37,总分排位!$B$2:$F$55,5,FALSE) -> 105 | G37: =VLOOKUP(B37,总分排位!$B$2:$J$55,9,FALSE) -> 74 | H37: =VLOOKUP(B37,单科排位!$A$2:$C$55,3,FALSE) -> 87 | I37: =VLOOKUP(B37,单科排位!$A$2:$E$55,5,FALSE) -> 11 | J37: =VLOOKUP(B37,单科排位!$A$2:$G$55,7,FALSE) -> 163 | K37: =VLOOKUP(B37,单科排位!$A$2:$I$55,9,FALSE) -> 63 | L37: =VLOOKUP(B37,单科排位!$A$2:$M$55,13,FALSE) -> 181 | M37: =VLOOKUP(B37,单科排位!$A$2:$Q$55,17,FALSE) -> 43 | N37: -23 | O37: 29
B38: 刘诗晨 | C38: 10638 | D38: 497 | E38: =VLOOKUP(B38,总分排位!$B$2:$F$55,5,FALSE) -> 13 | F38: =VLOOKUP(B38,总分排位!$B$2:$F$55,5,FALSE) -> 13 | G38: =VLOOKUP(B38,总分排位!$B$2:$J$55,9,FALSE) -> 28 | H38: =VLOOKUP(B38,单科排位!$A$2:$C$55,3,FALSE) -> 42 | I38: =VLOOKUP(B38,单科排位!$A$2:$E$55,5,FALSE) -> 38 | J38: =VLOOKUP(B38,单科排位!$A$2:$G$55,7,FALSE) -> 69 | K38: =VLOOKUP(B38,单科排位!$A$2:$I$55,9,FALSE) -> 48 | L38: =VLOOKUP(B38,单科排位!$A$2:$M$55,13,FALSE) -> 14 | M38: =VLOOKUP(B38,单科排位!$A$2:$Q$55,17,FALSE) -> 12 | N38: 9 | O38: 33
B39: 莫思桐 | C39: 10641 | D39: 435 | E39: =VLOOKUP(B39,总分排位!$B$2:$F$55,5,FALSE) -> 100 | F39: =VLOOKUP(B39,总分排位!$B$2:$F$55,5,FALSE) -> 100 | G39: =VLOOKUP(B39,总分排位!$B$2:$J$55,9,FALSE) -> 107 | H39: =VLOOKUP(B39,单科排位!$A$2:$C$55,3,FALSE) -> 19 | I39: =VLOOKUP(B39,单科排位!$A$2:$E$55,5,FALSE) -> 175 | J39: =VLOOKUP(B39,单科排位!$A$2:$G$55,7,FALSE) -> 69 | K39: =VLOOKUP(B39,单科排位!$A$2:$I$55,9,FALSE) -> 71 | L39: =VLOOKUP(B39,单科排位!$A$2:$M$55,13,FALSE) -> 52 | M39: =VLOOKUP(B39,单科排位!$A$2:$Q$55,17,FALSE) -> 60 | N39: -79 | O39: -26
A40: 7 | B40: 赖银婷 | C40: 10634 | D40: 556 | E40: =VLOOKUP(B40,总分排位!$B$2:$F$55,5,FALSE) -> 1 | F40: =VLOOKUP(B40,总分排位!$B$2:$F$55,5,FALSE) -> 1 | G40: =VLOOKUP(B40,总分排位!$B$2:$J$55,9,FALSE) -> 1 | H40: =VLOOKUP(B40,单科排位!$A$2:$C$55,3,FALSE) -> 19 | I40: =VLOOKUP(B40,单科排位!$A$2:$E$55,5,FALSE) -> 1 | J40: =VLOOKUP(B40,单科排位!$A$2:$G$55,7,FALSE) -> 34 | K40: =VLOOKUP(B40,单科排位!$A$2:$I$55,9,FALSE) -> 4 | L40: =VLOOKUP(B40,单科排位!$A$2:$M$55,13,FALSE) -> 12 | M40: =VLOOKUP(B40,单科排位!$A$2:$Q$55,17,FALSE) -> 16 | N40: -2 | O40: 1 | P40: =AVERAGE(F40:F45) -> 58.166667 | Q40: =AVERAGE(G40:G45) -> 64.166667 | R40: =AVERAGE(H40:H45) -> 96.833333 | S40: =AVERAGE(I40:I45) -> 79.833333 | T40: =AVERAGE(J40:J45) -> 61.166667 | U40: =AVERAGE(K40:K45) -> 63.5 | V40: =AVERAGE(L40:L45) -> 81.166667 | W40: =AVERAGE(M40:M45) -> 34.833333
...
